Workbook
Name bpe: #REF!
Name bpe: #REF!
Name bpe: SYNOPTIQUE!$B$276:$B$293
Name bpe: #REF!
Name Criteria: #REF!
Name Criteria: #REF!
Name Criteria: #REF!
Name Criteria: #REF!
Name Criteria: #REF!
Name Criteria: #REF!
Name Criteria: #REF!
Name Criteria: #REF!
Name Criteria: #REF!
Name Database: #REF!
Name Database: #REF!
Name Database: #REF!
Name Database: #REF!
Name Database: #REF!
Name Database: #REF!
Name Database: #REF!
Name Database: #REF!
Name Database: #REF!
Name ETAGE: #REF!
Name ETAGE: #REF!
Name ETAGE: SYNOPTIQUE!$B$180:$B$273
Name ETAGE: #REF!
Name Extract: #REF!
Name Extract: #REF!
Name Extract: #REF!
Name Extract: #REF!
Name Extract: #REF!
Name Extract: #REF!
Name Extract: #REF!
Name Extract: #REF!
Name Extract: #REF!
Name Liste: #REF!
Name Liste: #REF!
Name Liste: #REF!
Name Liste: #REF!
Name Liste: #REF!
Name Liste: #REF!
Name Liste: #REF!
Name Liste: #REF!
Name Liste: #REF!
Name O_N: #REF!
Name O_N: #REF!
Name O_N: SYNOPTIQUE!$B$176:$B$177
Name O_N: #REF!
Name Print_Area: Adduction!$A$1:$Z$70
Name Print_Area: Aiguillage!$A$1:$Z$63
Name Print_Area: Général!$A$1:$Z$69
Name Print_Area: 'Page de garde'!$A$1:$AB$74
Name Print_Area: 'Photos adduction'!$A$1:$AB$70
Name Print_Area: 'Photos Cheminement Exterieur'!$A$1:$AB$61
Name Print_Area: 'Photos Cheminement intérieur'!$A$1:$AB$60

Sheet Page de garde
F10: DOSSIER TECHNIQUE IMMEUBLE
F12: DOSSIER D'OUVRAGE EXÉCUTÉ
F14: {{idImmeuble}}-{{idImmeubleSysteme}}
F18: REF PM :{{idImmeuble}}
F19: {{idImmeubleSysteme}}
F21: {{ville}}
F23: {{idImmeuble}}-{{idImmeubleSysteme}}
D29: Proposition de câblage en fibre optique
D37: {{photo_facade}}
D69: abe@abedessin.fr ABE 01.42.00.03.54 V2 : 08/11/2016
D71: Interlocuteur : | K71: {{SYNDIC}}
D72: Fiche Établie par : | K72: {{User}} | R72: Date : | T72: =TODAY() -> 46157 | Z72: V0.1
A75: Evolutions depuis la version précédente :
A76: Ajout d'une colonne "Longueur" dans l'onglet CABLES
A77: Confirmation de la colonne "ETAGE_BPE" dans l'onglet BPE
A78: Définition des modes de remplisage de certaines colonnes

Sheet Général
F10: DOSSIER TECHNIQUE IMMEUBLE
F12: ='Page de garde'!F12:W12 -> DOSSIER D'OUVRAGE EXÉCUTÉ
D14: SYNDIC
D15: Nom: | J15: {{SYNDIC}}
D16: Adresse:
D20: Téléphone:
D21: Fax:
D22: Courriel:
D25: CONDITIONS D'ACCES
D26: Contact:
D27: Horaires:
D28: Digicode:
D29: Adresse complémentaire:
D33: INFORMATIONS IMMEUBLE
D34: Nombre de logements | M34: {{nbrB2C}}
D35: Nombre de locaux professionnels | M35: {{nbrB2B}}
D36: Nombre de locaux autre | M36: 0
D37: Nombre Total de prises | M37: {{totalClients}}
D38: Nombre de cages d'escalier | M38: 1
D39: Nombre de colonnes montantes | M39: 1
D40: Type d'adduction immeuble: | M40: SOUTERRAIN
D41: Emplacement de l'adduction | M41: GAINE TECHNIQUE DU RDC
D42: Passage en partie privative | M42: Non
D43: Percements nécessaires | M43: Non
D44: Pose de goulotte nécessaire | M44: Non
D45: Ouverture d'un coffrage nécessaire | M45: Non
D46: Date de réalisation des travaux
D47: Observations:
D53: Commentaires du gestionnaire
D59: Bon pour accord travaux :
D60: Fait à : | O60: Le :
D62: Signature du gestionnaire
D68: Interlocuteur : | K68: ='Page de garde'!K71:Y71 -> {{SYNDIC}}
D69: Fiche Établie par : | K69: ='Page de garde'!K72:Q72 -> {{User}} | Q69: Date : | S69: ='Page de garde'!T72 -> 46157

Sheet Aiguillage
F10: DOSSIER TECHNIQUE IMMEUBLE
F12: ='Page de garde'!F12:W12 -> DOSSIER D'OUVRAGE EXÉCUTÉ
D14: Plan des infrastructures Télécoms mobilisables
D15: {{plan_des_infrastructures}}
D60: Interlocuteur : | K60: ='Page de garde'!K71:Y71 -> {{SYNDIC}}
D61: Fiche Établie par : | K61: ='Page de garde'!K72:Q72 -> {{User}} | P61: Date : | R61: ='Page de garde'!T72 -> 46157

Sheet Adduction
F10: DOSSIER TECHNIQUE IMMEUBLE
F12: ='Page de garde'!F12:W12 -> DOSSIER D'OUVRAGE EXÉCUTÉ
D14: PLAN DE SITUATION
D15: {{plan_de_situation}}
D37: PLAN DE CHEMINEMENT ADDUCTION - BPO
D38: {{plan_de_cheminement}}
D67: Interlocuteur : | K67: ='Page de garde'!K71:Y71 -> {{SYNDIC}}
D68: Fiche Établie par : | K68: ='Page de garde'!K72:Q72 -> {{User}} | P68: Date : | R68: ='Page de garde'!T72 -> 46157

Sheet Photos adduction
F10: DOSSIER TECHNIQUE IMMEUBLE
F12: ='Page de garde'!F12:W12 -> DOSSIER D'OUVRAGE EXÉCUTÉ
D14: ADDUCTION - POINT DE PENETRATION
D15: Emplacement de l'adduction | N15: GT DU RDC
D16: Distance BPE / Bas de colonne montante | N16: 83 ml
D17: {{photo_adduction}}
D41: EMPLACEMENT BPO (GT DU RDC/2éme)
D42: {{emplacement_bpo1}} | O42: {{emplacement_bpo2}}
D67: Interlocuteur : | K67: ='Page de garde'!K71:Y71 -> {{SYNDIC}}
D68: Fiche Établie par : | K68: ='Page de garde'!K72:Q72 -> {{User}} | R68: Date : | T68: ='Page de garde'!T72:Y72 -> 46157

Sheet Photos Cheminement Exterieur
F10: DOSSIER TECHNIQUE IMMEUBLE
F12: ='Page de garde'!F12:W12 -> DOSSIER D'OUVRAGE EXÉCUTÉ
D14: PHOTOS DU CHEMINEMENT DEPUIS LA VOIE PUBLIQUE JUSQU'AU POINT D'ADDUCTION
D15: VUE DE SITUATION-CHAMBRE BPE | O15: CHAMBRE BPE OUVERTE MASQUE C
D16: {{situation_chambre_bpe}} | O16: {{bpe_ouverte}}
D29: Fixation BPE | O29: Ettiqutage CHA
D30: {{fixation_bpe}} | O30: {{ettiqutage_cha}}
D43: Ettiqtage PBO CHA
D44: {{ettiqtage_pbo1_cha}} | O44: {{ettiqtage_pbo2_cha}}
D59: Interlocuteur : | K59: ='Page de garde'!K71:Y71 -> {{SYNDIC}}
D60: Fiche Établie par : | K60: ='Page de garde'!K72:Q72 -> {{User}} | Q60: Date : | T60: ='Page de garde'!T72 -> 46157

Sheet Photos Cheminement intérieur
F10: DOSSIER TECHNIQUE IMMEUBLE
F12: AVANT PROJET DETAILLE
D14: PHOTOS DU BATIMENT
D15: PHOTO DU BATIMENT | O15: ENTREE DU BATIMENT
D16: {{photo_immeuble}} | O16: {{photo_entree}}
D29: GT DU RDC - POSE PBO | O29: GT DU 2éme- POSE PBO
D30: {{pose_pbo1}} | O30: {{pose_pbo2}}
D44: {{pose_pbo3}} | O44: {{pose_pbo4}}
D58: Interlocuteur :
D59: Fiche Établie par : | K59: {='Photos Cheminement Exterieur'!K60:P60} -> {{User}} | L59: 0 | M59: 0 | N59: 0 | O59: 0 | P59: 0 | Q59: Date : | T59: {='Photos Cheminement Exterieur'!T60:Y60} -> 46157 | U59: 0 | V59: 0 | W59: 0 | X59: 0 | Y59: 0

Sheet SYNOPTIQUE
B1: ID BAT | G1: {{idImmeuble}}-{{idImmeubleSysteme}}
B2: Batiment | G2: A
B3: Escalier | G3: A
B4: ID Colonne montante | G4: CM1
B5: BPE de rattachement | G5: BPE-EJA02-MRJ06-2136
B7: EXISTANT (1)/ INEXISTANT (0) | C7: NIVEAU | D7: ETAGE | E7: HAUTEUR ENTRE ETAGE | F7: NB DE LOGEMENTS RACCORDABLES | G7: NB DE LOCAUX PRO RACCORDABLES | H7: NB DE LOCAUX AUTRE RACCORDABLES | J7: NB RACCORDEMENTS PREVUS | K7: ID Provisoire ou définitif du BPE
K12: ID | L12: TYPE
B13: 1 | C13: 1 | D13: 4
B14: 1 | C14: 1 | D14: 4
B15: 1 | C15: 1 | D15: 4
B16: 1 | C16: 1 | D16: 4
B17: 1 | C17: 1 | D17: 3
B18: 1 | C18: 1 | D18: 3
B19: 1 | C19: 1 | D19: 3
B20: 1 | C20: 1 | D20: 3
B21: 1 | C21: 1 | D21: 2
B22: 1 | C22: 1 | D22: 2
B23: 1 | C23: 1 | D23: 2
B24: 1 | C24: 1 | D24: 2
... B28: 1 | C28: 1 | D28: 1
B29: 1 | C29: 1 | D29: RDC
B30: 1 | C30: 1 | D30: RDC
B31: 1 | C31: 1 | D31: RDC | E31: 3 | F31: 9 | G31: 0 | H31: 0 | J31: 9 | K31: BPO-EJA02-MRJ06-093 | L31: FBR
B32: 1 | C32: 0 | D32: RDC | E32: 3 | F32: 9 | G32: 6 | H32: 0 | J32: 9 | K32: BPO-EJA02-MRJ06-092 | L32: FBR
B33: 0 | C33: -1 | D33: -1
B34: 0 | C34: -2 | D34: -2
B35: 0 | C35: -3 | D35: -3
B36: 0 | C36: -4 | D36: -4
B37: 0 | C37: -5 | D37: -5
B38: 0 | C38: -6 | D38: -6
B40: total locaux | F40: 18
B175: O_N
B176: 1
B177: 0
B180: 23 H
B181: 23 B
B182: 23
B183: 22 H
B184: 22 B
B185: 22
...

Sheet LISTE DES LOCAUX
A1: ID | B1: ID_BAT | C1: BATIMENT | D1: ESCALIER | E1: CODE_ESCALIER | F1: ETAGE | G1: CODE ETAGE | H1: NUM | I1: EXTENSION | J1: QUALITE | K1: LOCALISATION OU ELEMENT DE DISCRIMINATION | L1: ID_PB | M1: Ml cable racco | N1: ID_PTO | O1: POSITION_TIROIR_DISTRIBUTION | P1: CABLE_PB | Q1: TUBE_PB | R1: FIBRE_PB
A2: 1 | B2: JAD-LAS0053-IMB-24010-AAADZ | C2: A | D2: A | E2: EJA02-MRJ0005-IMB-24010-AAADZ | F2: 0 | G2: EJA02-MRJ0005-IMB-24010-AAADZ | H2: 1 | J2: LOGEMENT | L2: PBO-EJA02-MRJ05-0092-2136 | M2: 116 | O2: TDI-06-EJA02-MRJ05-1225-073 | P2: 1 | Q2: T1 | R2: 1
A3: 2 | B3: JAD-LAS0053-IMB-24010-AAADZ | C3: A | D3: A | E3: EJA02-MRJ0005-IMB-24010-AAADZ | F3: 0 | G3: EJA02-MRJ0005-IMB-24010-AAADZ | H3: 2 | J3: LOGEMENT | L3: PBO-EJA02-MRJ05-0092-2136 | M3: 116 | O3: TDI-06-EJA02-MRJ05-1225-074 | P3: 2 | Q3: T1 | R3: 2
A4: 3 | B4: JAD-LAS0053-IMB-24010-AAADZ | C4: A | D4: A | E4: EJA02-MRJ0005-IMB-24010-AAADZ | F4: 0 | G4: EJA02-MRJ0005-IMB-24010-AAADZ | H4: 3 | J4: LOGEMENT | L4: PBO-EJA02-MRJ05-0092-2136 | M4: 116 | O4: TDI-06-EJA02-MRJ05-1225-075 | P4: 3 | Q4: T1 | R4: 3
A5: 4 | B5: JAD-LAS0053-IMB-24010-AAADZ | C5: A | D5: A | E5: EJA02-MRJ0005-IMB-24010-AAADZ | F5: 0 | G5: EJA02-MRJ0005-IMB-24010-AAADZ | H5: 4 | J5: LOGEMENT | L5: PBO-EJA02-MRJ05-0092-2136 | M5: 116 | O5: TDI-06-EJA02-MRJ05-1225-076 | P5: 4 | Q5: T1 | R5: 4
A6: 5 | B6: JAD-LAS0053-IMB-24010-AAADZ | C6: A | D6: A | E6: EJA02-MRJ0005-IMB-24010-AAADZ | F6: 1 | G6: EJA02-MRJ0005-IMB-24010-AAADZ | H6: 5 | J6: LOGEMENT | L6: PBO-EJA02-MRJ05-0092-2136 | M6: 116 | O6: TDI-06-EJA02-MRJ05-1225-077 | P6: 5 | Q6: T1 | R6: 5
A7: 6 | B7: JAD-LAS0053-IMB-24010-AAADZ | C7: A | D7: A | E7: EJA02-MRJ0005-IMB-24010-AAADZ | F7: 1 | G7: EJA02-MRJ0005-IMB-24010-AAADZ | H7: 6 | J7: LOGEMENT | L7: PBO-EJA02-MRJ05-0092-2136 | M7: 116 | O7: TDI-06-EJA02-MRJ05-1225-078 | P7: 6 | Q7: T1 | R7: 6
A8: 7 | B8: JAD-LAS0053-IMB-24010-AAADZ | C8: A | D8: A | E8: EJA02-MRJ0005-IMB-24010-AAADZ | F8: 1 | G8: EJA02-MRJ0005-IMB-24010-AAADZ | H8: 7 | J8: LOGEMENT | L8: PBO-EJA02-MRJ05-0092-2136 | M8: 116 | O8: TDI-06-EJA02-MRJ05-1225-079 | P8: 7 | Q8: T1 | R8: 7
A9: 8 | B9: JAD-LAS0053-IMB-24010-AAADZ | C9: A | D9: A | E9: EJA02-MRJ0005-IMB-24010-AAADZ | F9: 1 | G9: EJA02-MRJ0005-IMB-24010-AAADZ | H9: 8 | J9: LOGEMENT | L9: PBO-EJA02-MRJ05-0092-2136 | M9: 116 | O9: TDI-06-EJA02-MRJ05-1225-080 | P9: 8 | Q9: T1 | R9: 8
A10: 9 | B10: JAD-LAS0053-IMB-24010-AAADZ | C10: A | D10: A | E10: EJA02-MRJ0005-IMB-24010-AAADZ | F10: 1 | G10: EJA02-MRJ0005-IMB-24010-AAADZ | H10: 9 | J10: LOGEMENT | L10: PBO-EJA02-MRJ05-0092-2136 | M10: 116 | O10: TDI-06-EJA02-MRJ05-1225-081 | P10: 9 | Q10: T1 | R10: 9
A11: 10 | O11: TDI-06-EJA02-MRJ05-1225-082 | P11: R | Q11: R | R11: R
A12: 11 | O12: TDI-06-EJA02-MRJ05-1225-083 | P12: R | Q12: R | R12: R
A13: 12 | O13: TDI-06-EJA02-MRJ05-1225-084 | P13: R | Q13: R | R13: R
A14: 13 | B14: JAD-LAS0053-IMB-24010-AAADZ | C14: A | D14: A | E14: EJA02-MRJ0005-IMB-24010-AAADZ | F14: 2 | G14: EJA02-MRJ0005-IMB-24010-AAADZ | H14: 10 | J14: LOGEMENT | L14: PBO-EJA02-MRJ05-0093-2136 | M14: 116 | O14: TDI-06-EJA02-MRJ05-1225-085 | P14: 10 | Q14: T2 | R14: 1
A15: 14 | B15: JAD-LAS0053-IMB-24010-AAADZ | C15: A | D15: A | E15: EJA02-MRJ0005-IMB-24010-AAADZ | F15: 2 | G15: EJA02-MRJ0005-IMB-24010-AAADZ | H15: 11 | J15: LOGEMENT | L15: PBO-EJA02-MRJ05-0093-2136 | M15: 116 | O15: TDI-06-EJA02-MRJ05-1225-086 | P15: 11 | Q15: T2 | R15: 2
A16: 15 | B16: JAD-LAS0053-IMB-24010-AAADZ | C16: A | D16: A | E16: EJA02-MRJ0005-IMB-24010-AAADZ | F16: 2 | G16: EJA02-MRJ0005-IMB-24010-AAADZ | H16: 12 | J16: LOGEMENT | L16: PBO-EJA02-MRJ05-0093-2136 | M16: 116 | O16: TDI-06-EJA02-MRJ05-1225-087 | P16: 12 | Q16: T2 | R16: 3
A17: 16 | B17: JAD-LAS0053-IMB-24010-AAADZ | C17: A | D17: A | E17: EJA02-MRJ0005-IMB-24010-AAADZ | F17: 2 | G17: EJA02-MRJ0005-IMB-24010-AAADZ | H17: 13 | J17: LOGEMENT | L17: PBO-EJA02-MRJ05-0093-2136 | M17: 116 | O17: TDI-06-EJA02-MRJ05-1225-088 | P17: 13 | Q17: T2 | R17: 4
A18: 17 | B18: JAD-LAS0053-IMB-24010-AAADZ | C18: A | D18: A | E18: EJA02-MRJ0005-IMB-24010-AAADZ | F18: 2 | G18: EJA02-MRJ0005-IMB-24010-AAADZ | H18: 14 | J18: LOGEMENT | L18: PBO-EJA02-MRJ05-0093-2136 | M18: 116 | O18: TDI-06-EJA02-MRJ05-1225-089 | P18: 14 | Q18: T2 | R18: 5
A19: 18 | B19: JAD-LAS0053-IMB-24010-AAADZ | C19: A | D19: A | E19: EJA02-MRJ0005-IMB-24010-AAADZ | F19: 3 | G19: EJA02-MRJ0005-IMB-24010-AAADZ | H19: 15 | J19: LOGEMENT | L19: PBO-EJA02-MRJ05-0093-2136 | M19: 116 | O19: TDI-06-EJA02-MRJ05-1225-090 | P19: 15 | Q19: T2 | R19: 6
A20: 19 | B20: JAD-LAS0053-IMB-24010-AAADZ | C20: A | D20: A | E20: EJA02-MRJ0005-IMB-24010-AAADZ | F20: 3 | G20: EJA02-MRJ0005-IMB-24010-AAADZ | H20: 16 | J20: LOGEMENT | L20: PBO-EJA02-MRJ05-0093-2136 | M20: 116 | O20: TDI-06-EJA02-MRJ05-1225-091 | P20: 16 | Q20: T2 | R20: 7
A21: 20 | B21: JAD-LAS0053-IMB-24010-AAADZ | C21: A | D21: A | E21: EJA02-MRJ0005-IMB-24010-AAADZ | F21: 3 | G21: EJA02-MRJ0005-IMB-24010-AAADZ | H21: 17 | J21: LOGEMENT | L21: PBO-EJA02-MRJ05-0093-2136 | M21: 116 | O21: TDI-06-EJA02-MRJ05-1225-092 | P21: 17 | Q21: T2 | R21: 8
A22: 21 | B22: JAD-LAS0053-IMB-24010-AAADZ | C22: A | D22: A | E22: EJA02-MRJ0005-IMB-24010-AAADZ | F22: 3 | G22: EJA02-MRJ0005-IMB-24010-AAADZ | H22: 18 | J22: LOGEMENT | L22: PBO-EJA02-MRJ05-0093-2136 | M22: 116 | O22: TDI-06-EJA02-MRJ05-1225-093 | P22: 18 | Q22: T2 | R22: 9
A23: 22 | O23: TDI-06-EJA02-MRJ05-1225-094 | P23: R | Q23: R | R23: R
A24: 23 | O24: TDI-06-EJA02-MRJ05-1225-095 | P24: R | Q24: R | R24: R
A25: 24 | O25: TDI-06-EJA02-MRJ05-1225-096 | P25: R | Q25: R | R25: R

Sheet CABLES
A1: ID_CABLE | B1: CAPACITE | C1: MODULO | D1: BPE_ORIGINE | E1: PBO_EXTREMITE | F1: LONGUEUR (en metre) | G1: EMPRISE
A2: CDI-UNF-EJA02-MRJ05-24F-0092 | B2: 12 | C2: 12 | D2: BPE-EJA02-MRJ006-2136 | E2: PBO-EJA02-MRJ005-0092 | F2: 71 | G2: SOUTERRAIN PUIS GAINE TECHNIQUE
A3: CDI-UNF-EJA02-MRJ05-24F-0093 | B3: 12 | C3: 12 | D3: BPE-EJA02-MRJ006-2136 | E3: PBO-EJA02-MRJ005-0093 | F3: 12 | G3: GAINE TECHNIQUE

Sheet BPE
A1: BPE | B1: MODELE BPE | C1: EMPLACEMENT BPE | D1: TYPE EMPLACEMENT BPE | E1: ETAGE_BPE | F1: HAUTEUR BPE (PH<2.5m, 2.5<MH<4.5m et GH>4.5m) | G1: NB_RACCORDEMENTS PREVUS | H1: TUBE_UTIL_1 | I1: TUBE_UTIL_2
A2: BPE-EJA02-MRJ05-2136 | B2: FBR | C2: chambre L2T | D2: PointTechnique | E2: 0 | F2: PH | G2: 18 | H2: 7 | I2: 8

Sheet CABLAGE BPE HORS PBO
A1: PT ou LT | B1: BPE | C1: TYPE_BPE | D1: CASSETTE | E1: CABLE_G | F1: TUBE_G | G1: FIBRE_G | H1: POSITION | I1: CONNEXION | J1: TUBE_D | K1: TUBE_D | L1: CABLE_D | AC1: POINT_TECH | AD1: BPE | AE1: CABLE_G | AF1: CABLE_D
A2: CHA-IAM-EJA02-MRJ05-2136 | B2: BPE-EJA02-MRJ05-2136 | C2: FBR 144 - 12x12 | D2: CAS-1 | E2: CDI-UNF-JAD02-MAR005-144F-2136 | F2: T7 | G2: 1 | H2: 73 | I2: EPISSUREE | J2: T1 | K2: 1 | L2: CDI-UNF-EJA02-MAR005-24F-0092
A3: CHA-IAM-EJA02-MRJ05-2136 | B3: BPE-EJA02-MRJ05-2136 | C3: FBR 144 - 12x12 | D3: CAS-1 | E3: CDI-UNF-JAD02-MAR005-144F-2136 | F3: T7 | G3: 2 | H3: 74 | I3: EPISSUREE | J3: T1 | K3: 2 | L3: CDI-UNF-EJA02-MAR005-24F-0092
A4: CHA-IAM-EJA02-MRJ05-2136 | B4: BPE-EJA02-MRJ05-2136 | C4: FBR 144 - 12x12 | D4: CAS-1 | E4: CDI-UNF-JAD02-MAR005-144F-2136 | F4: T7 | G4: 3 | H4: 75 | I4: EPISSUREE | J4: T1 | K4: 3 | L4: CDI-UNF-EJA02-MAR005-24F-0092
A5: CHA-IAM-EJA02-MRJ05-2136 | B5: BPE-EJA02-MRJ05-2136 | C5: FBR 144 - 12x12 | D5: CAS-1 | E5: CDI-UNF-JAD02-MAR005-144F-2136 | F5: T7 | G5: 4 | H5: 76 | I5: EPISSUREE | J5: T1 | K5: 4 | L5: CDI-UNF-EJA02-MAR005-24F-0092
A6: CHA-IAM-EJA02-MRJ05-2136 | B6: BPE-EJA02-MRJ05-2136 | C6: FBR 144 - 12x12 | D6: CAS-1 | E6: CDI-UNF-JAD02-MAR005-144F-2136 | F6: T7 | G6: 5 | H6: 77 | I6: EPISSUREE | J6: T1 | K6: 5 | L6: CDI-UNF-EJA02-MAR005-24F-0092
A7: CHA-IAM-EJA02-MRJ05-2136 | B7: BPE-EJA02-MRJ05-2136 | C7: FBR 144 - 12x12 | D7: CAS-1 | E7: CDI-UNF-JAD02-MAR005-144F-2136 | F7: T7 | G7: 6 | H7: 78 | I7: EPISSUREE | J7: T1 | K7: 6 | L7: CDI-UNF-EJA02-MAR005-24F-0092
A8: CHA-IAM-EJA02-MRJ05-2136 | B8: BPE-EJA02-MRJ05-2136 | C8: FBR 144 - 12x12 | D8: CAS-1 | E8: CDI-UNF-JAD02-MAR005-144F-2136 | F8: T7 | G8: 7 | H8: 79 | I8: EPISSUREE | J8: T1 | K8: 7 | L8: CDI-UNF-EJA02-MAR005-24F-0092
A9: CHA-IAM-EJA02-MRJ05-2136 | B9: BPE-EJA02-MRJ05-2136 | C9: FBR 144 - 12x12 | D9: CAS-1 | E9: CDI-UNF-JAD02-MAR005-144F-2136 | F9: T7 | G9: 8 | H9: 80 | I9: EPISSUREE | J9: T1 | K9: 8 | L9: CDI-UNF-EJA02-MAR005-24F-0092
A10: CHA-IAM-EJA02-MRJ05-2136 | B10: BPE-EJA02-MRJ05-2136 | C10: FBR 144 - 12x12 | D10: CAS-1 | E10: CDI-UNF-JAD02-MAR005-144F-2136 | F10: T7 | G10: 9 | H10: 81 | I10: EPISSUREE | J10: T1 | K10: 9 | L10: CDI-UNF-EJA02-MAR005-24F-0092
A11: CHA-IAM-EJA02-MRJ05-2136 | B11: BPE-EJA02-MRJ05-2136 | C11: FBR 144 - 12x12 | D11: CAS-1 | E11: CDI-UNF-JAD02-MAR005-144F-2136 | F11: T7 | G11: 10 | H11: 82 | I11: RESERVE | J11: T1 | K11: 10
A12: CHA-IAM-EJA02-MRJ05-2136 | B12: BPE-EJA02-MRJ05-2136 | C12: FBR 144 - 12x12 | D12: CAS-1 | E12: CDI-UNF-JAD02-MAR005-144F-2136 | F12: T7 | G12: 11 | H12: 83 | I12: RESERVE | J12: T1 | K12: 11
A13: CHA-IAM-EJA02-MRJ05-2136 | B13: BPE-EJA02-MRJ05-2136 | C13: FBR 144 - 12x12 | D13: CAS-1 | E13: CDI-UNF-JAD02-MAR005-144F-2136 | F13: T7 | G13: 12 | H13: 84 | I13: RESERVE | J13: T1 | K13: 12
A14: CHA-IAM-EJA02-MRJ05-2136 | B14: BPE-EJA02-MRJ05-2136 | C14: FBR 144 - 12x12 | D14: CAS-2 | E14: CDI-UNF-JAD02-MAR005-144F-2136 | F14: T8 | G14: 1 | H14: 85 | I14: EPISSUREE | J14: T2 | K14: 1 | L14: CDI-UNF-EJA02-MAR005-24F-0093
A15: CHA-IAM-EJA02-MRJ05-2136 | B15: BPE-EJA02-MRJ05-2136 | C15: FBR 144 - 12x12 | D15: CAS-2 | E15: CDI-UNF-JAD02-MAR005-144F-2136 | F15: T8 | G15: 2 | H15: 86 | I15: EPISSUREE | J15: T2 | K15: 2 | L15: CDI-UNF-EJA02-MAR005-24F-0093
A16: CHA-IAM-EJA02-MRJ05-2136 | B16: BPE-EJA02-MRJ05-2136 | C16: FBR 144 - 12x12 | D16: CAS-2 | E16: CDI-UNF-JAD02-MAR005-144F-2136 | F16: T8 | G16: 3 | H16: 87 | I16: EPISSUREE | J16: T2 | K16: 3 | L16: CDI-UNF-EJA02-MAR005-24F-0093
A17: CHA-IAM-EJA02-MRJ05-2136 | B17: BPE-EJA02-MRJ05-2136 | C17: FBR 144 - 12x12 | D17: CAS-2 | E17: CDI-UNF-JAD02-MAR005-144F-2136 | F17: T8 | G17: 4 | H17: 88 | I17: EPISSUREE | J17: T2 | K17: 4 | L17: CDI-UNF-EJA02-MAR005-24F-0093
A18: CHA-IAM-EJA02-MRJ05-2136 | B18: BPE-EJA02-MRJ05-2136 | C18: FBR 144 - 12x12 | D18: CAS-2 | E18: CDI-UNF-JAD02-MAR005-144F-2136 | F18: T8 | G18: 5 | H18: 89 | I18: EPISSUREE | J18: T2 | K18: 5 | L18: CDI-UNF-EJA02-MAR005-24F-0093
A19: CHA-IAM-EJA02-MRJ05-2136 | B19: BPE-EJA02-MRJ05-2136 | C19: FBR 144 - 12x12 | D19: CAS-2 | E19: CDI-UNF-JAD02-MAR005-144F-2136 | F19: T8 | G19: 6 | H19: 90 | I19: EPISSUREE | J19: T2 | K19: 6 | L19: CDI-UNF-EJA02-MAR005-24F-0093
A20: CHA-IAM-EJA02-MRJ05-2136 | B20: BPE-EJA02-MRJ05-2136 | C20: FBR 144 - 12x12 | D20: CAS-2 | E20: CDI-UNF-JAD02-MAR005-144F-2136 | F20: T8 | G20: 7 | H20: 91 | I20: EPISSUREE | J20: T2 | K20: 7 | L20: CDI-UNF-EJA02-MAR005-24F-0093
A21: CHA-IAM-EJA02-MRJ05-2136 | B21: BPE-EJA02-MRJ05-2136 | C21: FBR 144 - 12x12 | D21: CAS-2 | E21: CDI-UNF-JAD02-MAR005-144F-2136 | F21: T8 | G21: 8 | H21: 92 | I21: EPISSUREE | J21: T2 | K21: 8 | L21: CDI-UNF-EJA02-MAR005-24F-0093
A22: CHA-IAM-EJA02-MRJ05-2136 | B22: BPE-EJA02-MRJ05-2136 | C22: FBR 144 - 12x12 | D22: CAS-2 | E22: CDI-UNF-JAD02-MAR005-144F-2136 | F22: T8 | G22: 9 | H22: 93 | I22: EPISSUREE | J22: T2 | K22: 9 | L22: CDI-UNF-EJA02-MAR005-24F-0093
A23: CHA-IAM-EJA02-MRJ05-2136 | B23: BPE-EJA02-MRJ05-2136 | C23: FBR 144 - 12x12 | D23: CAS-2 | E23: CDI-UNF-JAD02-MAR005-144F-2136 | F23: T8 | G23: 10 | H23: 94 | I23: RESERVE | J23: T2 | K23: 10
A24: CHA-IAM-EJA02-MRJ05-2136 | B24: BPE-EJA02-MRJ05-2136 | C24: FBR 144 - 12x12 | D24: CAS-2 | E24: CDI-UNF-JAD02-MAR005-144F-2136 | F24: T8 | G24: 11 | H24: 95 | I24: RESERVE | J24: T2 | K24: 11
A25: CHA-IAM-EJA02-MRJ05-2136 | B25: BPE-EJA02-MRJ05-2136 | C25: FBR 144 - 12x12 | D25: CAS-2 | E25: CDI-UNF-JAD02-MAR005-144F-2136 | F25: T8 | G25: 12 | H25: 96 | I25: RESERVE | J25: T2 | K25: 12

Sheet MATERIEL
B2: MATERIEL
B3: Type | C3: Référence | D3: Quantité
B4: PBO | C4: FBR | D4: 2
B5: BPE | C5: FBR | D5: 1
B6: CABLE D'ADDUCTION | C6: 24FO-MOD12_G657A1 | D6: 83ML | E6: TOTAL DE CABLE FO depuis BPE jusqu’à la derniere PBO
